<mujoco>
	
	<option timestep="0.001" integrator="RK4" gravity="0 0 -9.81">
		<flag sensornoise="enable" contact="enable" energy="enable"/>
	</option>

	<worldbody>
    	<!-- <light diffuse=".5 .5 .5" pos="0 0 3" dir="0 0 -1"/> -->
		<!-- <light mode="targetbody" target="torso"/> -->
        <light name="spotlight" mode="targetbodycom" target="leg" pos="0 -1 2"/>
		<body name="hopper1" pos="0 0 2">
            <!-- 约束跳跃机器人只在x和z方向自由 -->
            <!-- <freejoint/> -->
			<joint name="x" type="slide" pos="0 0 0" axis="1 0 0"/>
			<joint name="z" type="slide" pos="0 0 0" axis="0 0 1"/>

			<geom type="sphere" size=".1" rgba=".9 .9 .9 1" mass="1"/>
			<body name="leg" pos="0 0 -0.5" euler="0 0 0">
				<joint name="hip" type="hinge" pos="0 0 0.5" axis="0 -1 0" />
				<inertial pos="0. 0. 0." mass="1."
					fullinertia="0.085821 0.049222 0.08626 1.276e-05 -0.00016022 -0.000414"/>
				<geom type="cylinder" size=".05 .5" rgba="0 .9 0 1"/>

				<body name="foot" pos="0 0 -0.75">
					<joint name="knee" type="slide" pos="0 0 0.25" axis="0 0 -1"/>
					<geom type="cylinder" pos="0 0 0.125" size=".01 .125" rgba="0 0 .9 1" mass="0"/>
					<geom type="sphere" size=".05" rgba=".9 .9 0 1" mass="0.1"/>
				</body>
			</body>
		</body>
	</worldbody>

	<actuator>
		<position name="pservo-hip" joint="hip" kp="0"/>
		<velocity name="vservo-hip" joint="hip" kv="0"/>
		<position name="pservo-knee" joint="knee" kp="0"/>
		<velocity name="vservo-knee" joint="knee" kv="0"/>
	</actuator>

	<sensor>
		<jointpos name="hip_pos_sensor" joint="hip" noise="0.2"/>
		<jointvel name="hip_vel_sensor" joint="hip" noise="1"/>
	</sensor>


</mujoco>
