<mujoco>

	<option timestep="0.001" integrator="RK4" gravity="0 0 -9.81">
		<flag sensornoise="enable" contact="enable" energy="enable" />
	</option>

	<statistic center="0 0 0.55" extent="1.1" />

	<visual>
		<headlight diffuse="0.6 0.6 0.6" ambient="0.3 0.3 0.3" specular="0 0 0" />
		<rgba haze="0.15 0.25 0.35 1" />
		<global azimuth="150" elevation="-20" />
	</visual>


	<worldbody>
		<light diffuse=".5 .5 .5" pos="0 0 3" dir="0 0 -1"/>
		<body name="hopper" pos="0 0 2.5">
			<!-- 约束跳跃机器人只在x和z方向自由 -->
			<!-- <freejoint/>  -->
			<joint name="x" type="slide" pos="0 0 0" axis="1 0 0" />
			<joint name="z" type="slide" pos="0 0 0" axis="0 0 1" />

			<geom type="box" size=".5 .2 .09" rgba=".9 .9 .9 1" mass="1" />
			<site name="imu" size="0.01" pos="0 0 0" />
			<body name="thigh_left" pos="-0.5 0 -0.5" euler="0 45 0">
				<joint name="hip_left" type="hinge" pos="0 0 0.5" axis="0 -1 0" />
				<geom type="cylinder" size=".05 .5" rgba="0 .9 0 1" />
				<site name="s_left" pos="0 0 -0.5" />
				<body name="leg_left" pos=".5 0 -0.5" euler="0 -90 0">
					<joint name="knee_left" type="hinge" pos="0 0 0.5" axis="0 -1 0" />
					<geom type="cylinder" size=".05 .5" rgba="0 .9 0 1" />
				</body>
			</body>
			<body name="thigh_right" pos="0.5 0 -0.5" euler="0 -45 0">
				<joint name="hip_right" type="hinge" pos="0 0 0.5" axis="0 -1 0" />
				<geom type="cylinder" size=".05 .5" rgba="0 .9 0 1" />
				<site name="s_right" pos="0 0 -0.5" />
				<body name="leg_right" pos="-.5 0 -0.5" euler="0 90 0">
					<joint name="knee_right" type="hinge" pos="0 0 0.5" axis="0 -1 0" />
					<geom type="cylinder" size=".05 .5" rgba="0 .9 0 1" />
				</body>
			</body>
		</body>
		<body name="foot" pos="0 0 1">
			<freejoint />
			<geom type="box" size=".2 .2 .1" rgba=".9 .9 .0 1" mass="1" />
		</body>
	</worldbody>

	<contact>
		<exclude name="e0" body1="hopper" body2="thigh_left" />
		<exclude name="e1" body1="hopper" body2="thigh_right" />
		<exclude name="e2" body1="thigh_left" body2="leg_left" />
		<exclude name="e3" body1="thigh_right" body2="leg_right" />
		<exclude name="e4" body1="leg_left" body2="foot" />
		<exclude name="e5" body1="leg_right" body2="foot" />
	</contact>

	<equality>
		<connect name="c1" body1="leg_left" body2="foot" anchor="0 0 -0.5" />
		<connect name="c2" body1="leg_right" body2="foot" anchor="0 0 -0.5" />
	</equality>

	<tendon>
		<spatial range="1 2.5" limited="true" width=".02" rgba=".95 .3 .3 1" stiffness="30000"
			damping="10">
			<site site="s_left" />
			<site site="s_right" />
		</spatial>
	</tendon>

	<actuator>
		<motor name="left-hip-roll" joint="hip_left" gear="25" ctrlrange="-2 2" ctrllimited="true"
			user="2900" />
		<motor name="right-hip-roll" joint="hip_right" gear="25" ctrlrange="-2 2" ctrllimited="true"
			user="2900" />
		<!-- <position name="pservo-hip_left" joint="hip_left" kp="0"/>
		<velocity name="vservo-hip_left" joint="hip_left" kv="0"/>
		<position name="pservo-hip_right" joint="hip_right" kp="0"/>
		<velocity name="vservo-hip_right" joint="hip_right" kv="0"/> -->

	</actuator>

	<sensor>
		<!-- <jointpos name="hip_pos_sensor" joint="hip_left" noise="0" /> -->
		<!-- <jointvel name="hip_vel_sensor" joint="hip_left" noise="0" /> -->
		<framequat name="pelvis-orientation" objtype="site" objname="imu" />
		<gyro name="pelvis-angular-velocity" site="imu" noise="5e-4" cutoff="34.9" />
		<accelerometer name="pelvis-linear-acceleration" site="imu" noise="1e-2" cutoff="157" />
		<!-- <magnetometer name="pelvis-magnetometer" site="imu" /> -->
	</sensor>


</mujoco>