<mujoco>
	<!-- 根据dsh提供的参数建模 -->
	<option timestep="0.00001" integrator="RK4" gravity="0 0 -10">
		<flag sensornoise="enable" contact="enable" energy="enable" />
	</option>

	<statistic center="0 0 0.55" extent="1.1" />

	<visual>
		<headlight diffuse="0.6 0.6 0.6" ambient="0.3 0.3 0.3" specular="0 0 0" />
		<rgba haze="0.15 0.25 0.35 1" />
		<global azimuth="150" elevation="-20" />
	</visual>

	<default>
		<equality solref="0.005 1" />
	</default>

	<worldbody>
		<light diffuse=".5 .5 .5" pos="0 0 3" dir="0 0 -1" />
		<body name="hopper" pos="0 0 2">
			<!-- 约束跳跃机器人只在x和z方向自由 -->
			<freejoint />
			<geom type="box" size=".7 .2 .04" rgba=".9 .9 .9 1" mass="0.5" />
			<site name="imu" size="0.01" pos="0 0 0" />
			<body name="thigh_left" pos="-0.6179 0 -0.1179" euler="0 45 0">
				<joint name="hip_left" type="hinge" pos="0 0 0.1667" axis="0 -1 0" range="-45 90"
					limited="true" />
				<geom type="cylinder" size=".05 .1667" rgba="0 .9 0 1" mass="0.5" />
				<site name="s_left" pos="0 0 -0.1667" />
				<body name="leg_left" pos="0.1667 0 -0.1179" euler="0 -90 0">
					<joint name="knee_left" type="hinge" pos="0 0 0.1667" axis="0 -1 0" />
					<geom type="cylinder" size=".05 .1667" rgba="0 .9 0 1" mass="0.5" />
				</body>
			</body>
			<body name="thigh_right" pos="0.6179 0 -0.1179" euler="0 -45 0">
				<joint name="hip_right" type="hinge" pos="0 0 0.1667" axis="0 -1 0" range="-90 45"
					limited="true" />
				<geom type="cylinder" size=".05 .1667" rgba="0 .9 0 1" mass="0.5" />
				<site name="s_right" pos="0 0 -0.1667" />
				<body name="leg_right" pos="-0.1667 0 -0.1179" euler="0 90 0">
					<joint name="knee_right" type="hinge" pos="0 0 0.1667" axis="0 -1 0" />
					<geom type="cylinder" size=".05 .1667" rgba="0 .9 0 1" mass="0.5" />
				</body>
			</body>
		</body>
		<body name="foot" pos="0 0 1.5286">
			<freejoint />
			<geom type="box" size=".6 .2 .05" rgba=".9 .9 .0 1" mass="0.5" />
			<site name="foot_ground" pos="0 0 -0.055" />
		</body>
	</worldbody>

	<contact>
		<exclude name="e0" body1="hopper" body2="thigh_left" />
		<exclude name="e1" body1="hopper" body2="thigh_right" />
		<exclude name="e2" body1="thigh_left" body2="leg_left" />
		<exclude name="e3" body1="thigh_right" body2="leg_right" />
		<exclude name="e4" body1="leg_left" body2="foot" />
		<exclude name="e5" body1="leg_right" body2="foot" />
	</contact>

	<equality>
		<connect name="c1" body1="leg_left" body2="foot" anchor="0 0 -0.1667" />
		<connect name="c2" body1="leg_right" body2="foot" anchor="0 0 -0.1667" />
	</equality>

	<tendon>
		<spatial name='tendon1' range="0.1 10" limited="true" width=".02" rgba=".95 .3 .3 1"
			stiffness="50" springlength="0.25">
			<site site="s_left" />
			<site site="s_right" />
		</spatial>
	</tendon>

	<actuator>
		<position name="pservo_hip_left" joint="hip_left" kp="0" />
		<velocity name="vservo_hip_left" joint="hip_left" kv="0" />
		<position name="pservo_hip_right" joint="hip_right" kp="0" />
		<velocity name="vservo_hip_right" joint="hip_right" kv="0" />
	</actuator>

	<sensor>
		<jointpos name="hip_pos_sensor" joint="hip_left" noise="0" />
		<jointvel name="hip_vel_sensor" joint="hip_left" noise="0" />
		<accelerometer name="acceleration_sensor" site="imu" />
		<velocimeter name="velocity_sensor" site="imu" />
		<force name="ground_force_sensor" site="foot_ground" />
	</sensor>

</mujoco>